[2025-05-02T19:32:01.980+0000] {local_task_job_runner.py:123} INFO - ::group::Pre task execution logs
[2025-05-02T19:32:02.028+0000] {taskinstance.py:2614} INFO - Dependencies all met for dep_context=non-requeueable deps ti=<TaskInstance: google_maps_reviews.run_dbt_models manual__2025-05-02T19:25:35.067225+00:00 [queued]>
[2025-05-02T19:32:02.049+0000] {taskinstance.py:2614} INFO - Dependencies all met for dep_context=requeueable deps ti=<TaskInstance: google_maps_reviews.run_dbt_models manual__2025-05-02T19:25:35.067225+00:00 [queued]>
[2025-05-02T19:32:02.069+0000] {taskinstance.py:2867} INFO - Starting attempt 2 of 2
[2025-05-02T19:32:02.095+0000] {taskinstance.py:2890} INFO - Executing <Task(BashOperator): run_dbt_models> on 2025-05-02 19:25:35.067225+00:00
[2025-05-02T19:32:02.117+0000] {warnings.py:112} WARNING - /home/***/.local/lib/python3.12/site-packages/***/task/task_runner/standard_task_runner.py:70: DeprecationWarning: This process (pid=1284) is multi-threaded, use of fork() may lead to deadlocks in the child.
  pid = os.fork()

[2025-05-02T19:32:02.122+0000] {standard_task_runner.py:72} INFO - Started process 1299 to run task
[2025-05-02T19:32:02.123+0000] {standard_task_runner.py:104} INFO - Running: ['***', 'tasks', 'run', 'google_maps_reviews', 'run_dbt_models', 'manual__2025-05-02T19:25:35.067225+00:00', '--job-id', '160', '--raw', '--subdir', 'DAGS_FOLDER/***dag.py', '--cfg-path', '/tmp/tmpjw1hch2v']
[2025-05-02T19:32:02.125+0000] {standard_task_runner.py:105} INFO - Job 160: Subtask run_dbt_models
[2025-05-02T19:32:02.224+0000] {task_command.py:467} INFO - Running <TaskInstance: google_maps_reviews.run_dbt_models manual__2025-05-02T19:25:35.067225+00:00 [running]> on host 6ca499d7a39a
[2025-05-02T19:32:02.381+0000] {taskinstance.py:3134} INFO - Exporting env vars: AIRFLOW_CTX_DAG_OWNER='***' AIRFLOW_CTX_DAG_ID='google_maps_reviews' AIRFLOW_CTX_TASK_ID='run_dbt_models' AIRFLOW_CTX_EXECUTION_DATE='2025-05-02T19:25:35.067225+00:00' AIRFLOW_CTX_TRY_NUMBER='2' AIRFLOW_CTX_DAG_RUN_ID='manual__2025-05-02T19:25:35.067225+00:00'
[2025-05-02T19:32:02.385+0000] {logging_mixin.py:190} INFO - Task instance is in running state
[2025-05-02T19:32:02.386+0000] {logging_mixin.py:190} INFO -  Previous state of the Task instance: queued
[2025-05-02T19:32:02.388+0000] {logging_mixin.py:190} INFO - Current task name:run_dbt_models state:running start_date:2025-05-02 19:32:02.029608+00:00
[2025-05-02T19:32:02.389+0000] {logging_mixin.py:190} INFO - Dag name:google_maps_reviews and current dag run status:running
[2025-05-02T19:32:02.390+0000] {taskinstance.py:732} INFO - ::endgroup::
[2025-05-02T19:32:02.392+0000] {subprocess.py:78} INFO - Tmp dir root location: /tmp
[2025-05-02T19:32:02.395+0000] {subprocess.py:88} INFO - Running command: ['/usr/bin/bash', '-c', 'cd /opt/***/dbt_project/bank_reviews_dbt && dbt run']
[2025-05-02T19:32:02.426+0000] {subprocess.py:99} INFO - Output:
[2025-05-02T19:32:06.407+0000] {subprocess.py:106} INFO - Usage: dbt run [OPTIONS]
[2025-05-02T19:32:06.409+0000] {subprocess.py:106} INFO - Try 'dbt run -h' for help.
[2025-05-02T19:32:06.411+0000] {subprocess.py:106} INFO - 
[2025-05-02T19:32:06.412+0000] {subprocess.py:106} INFO - Error: Invalid value for '--profiles-dir': Path '/home/***/.dbt' does not exist.
[2025-05-02T19:32:06.900+0000] {subprocess.py:110} INFO - Command exited with return code 2
[2025-05-02T19:32:06.924+0000] {taskinstance.py:3313} ERROR - Task failed with exception
Traceback (most recent call last):
  File "/home/airflow/.local/lib/python3.12/site-packages/airflow/models/taskinstance.py", line 768, in _execute_task
    result = _execute_callable(context=context, **execute_callable_kwargs)
             ^^^^^^^^^^^^^^^^^^^^^^^^^^^^^^^^^^^^^^^^^^^^^^^^^^^^^^^^^^^^^
  File "/home/airflow/.local/lib/python3.12/site-packages/airflow/models/taskinstance.py", line 734, in _execute_callable
    return ExecutionCallableRunner(
           ^^^^^^^^^^^^^^^^^^^^^^^^
  File "/home/airflow/.local/lib/python3.12/site-packages/airflow/utils/operator_helpers.py", line 252, in run
    return self.func(*args, **kwargs)
           ^^^^^^^^^^^^^^^^^^^^^^^^^^
  File "/home/airflow/.local/lib/python3.12/site-packages/airflow/models/baseoperator.py", line 424, in wrapper
    return func(self, *args, **kwargs)
           ^^^^^^^^^^^^^^^^^^^^^^^^^^^
  File "/home/airflow/.local/lib/python3.12/site-packages/airflow/operators/bash.py", line 276, in execute
    raise AirflowException(
airflow.exceptions.AirflowException: Bash command failed. The command returned a non-zero exit code 2.
[2025-05-02T19:32:06.935+0000] {logging_mixin.py:190} INFO - Task instance in failure state
[2025-05-02T19:32:06.936+0000] {logging_mixin.py:190} INFO - Task start:2025-05-02 19:32:02.029608+00:00 end:2025-05-02 19:32:06.933016+00:00 duration:4.903408
[2025-05-02T19:32:06.937+0000] {logging_mixin.py:190} INFO - Task:<Task(BashOperator): run_dbt_models> dag:<DAG: google_maps_reviews> dagrun:<DagRun google_maps_reviews @ 2025-05-02 19:25:35.067225+00:00: manual__2025-05-02T19:25:35.067225+00:00, state:running, queued_at: 2025-05-02 19:25:35.100723+00:00. externally triggered: True>
[2025-05-02T19:32:06.938+0000] {logging_mixin.py:190} INFO - Failure caused by Bash command failed. The command returned a non-zero exit code 2.
[2025-05-02T19:32:06.940+0000] {taskinstance.py:1226} INFO - Marking task as FAILED. dag_id=google_maps_reviews, task_id=run_dbt_models, run_id=manual__2025-05-02T19:25:35.067225+00:00, execution_date=20250502T192535, start_date=20250502T193202, end_date=20250502T193206
[2025-05-02T19:32:06.998+0000] {taskinstance.py:341} INFO - ::group::Post task execution logs
[2025-05-02T19:32:07.000+0000] {standard_task_runner.py:124} ERROR - Failed to execute job 160 for task run_dbt_models (Bash command failed. The command returned a non-zero exit code 2.; 1299)
Traceback (most recent call last):
  File "/home/airflow/.local/lib/python3.12/site-packages/airflow/task/task_runner/standard_task_runner.py", line 117, in _start_by_fork
    ret = args.func(args, dag=self.dag)
          ^^^^^^^^^^^^^^^^^^^^^^^^^^^^^
  File "/home/airflow/.local/lib/python3.12/site-packages/airflow/cli/cli_config.py", line 49, in command
    return func(*args, **kwargs)
           ^^^^^^^^^^^^^^^^^^^^^
  File "/home/airflow/.local/lib/python3.12/site-packages/airflow/utils/cli.py", line 116, in wrapper
    return f(*args, **kwargs)
           ^^^^^^^^^^^^^^^^^^
  File "/home/airflow/.local/lib/python3.12/site-packages/airflow/cli/commands/task_command.py", line 483, in task_run
    task_return_code = _run_task_by_selected_method(args, _dag, ti)
                       ^^^^^^^^^^^^^^^^^^^^^^^^^^^^^^^^^^^^^^^^^^^^
  File "/home/airflow/.local/lib/python3.12/site-packages/airflow/cli/commands/task_command.py", line 256, in _run_task_by_selected_method
    return _run_raw_task(args, ti)
           ^^^^^^^^^^^^^^^^^^^^^^^
  File "/home/airflow/.local/lib/python3.12/site-packages/airflow/cli/commands/task_command.py", line 341, in _run_raw_task
    return ti._run_raw_task(
           ^^^^^^^^^^^^^^^^^
  File "/home/airflow/.local/lib/python3.12/site-packages/airflow/utils/session.py", line 97, in wrapper
    return func(*args, session=session, **kwargs)
           ^^^^^^^^^^^^^^^^^^^^^^^^^^^^^^^^^^^^^^
  File "/home/airflow/.local/lib/python3.12/site-packages/airflow/models/taskinstance.py", line 3006, in _run_raw_task
    return _run_raw_task(
           ^^^^^^^^^^^^^^
  File "/home/airflow/.local/lib/python3.12/site-packages/airflow/models/taskinstance.py", line 274, in _run_raw_task
    TaskInstance._execute_task_with_callbacks(
  File "/home/airflow/.local/lib/python3.12/site-packages/airflow/models/taskinstance.py", line 3161, in _execute_task_with_callbacks
    result = self._execute_task(context, task_orig)
             ^^^^^^^^^^^^^^^^^^^^^^^^^^^^^^^^^^^^^^
  File "/home/airflow/.local/lib/python3.12/site-packages/airflow/models/taskinstance.py", line 3185, in _execute_task
    return _execute_task(self, context, task_orig)
           ^^^^^^^^^^^^^^^^^^^^^^^^^^^^^^^^^^^^^^^
  File "/home/airflow/.local/lib/python3.12/site-packages/airflow/models/taskinstance.py", line 768, in _execute_task
    result = _execute_callable(context=context, **execute_callable_kwargs)
             ^^^^^^^^^^^^^^^^^^^^^^^^^^^^^^^^^^^^^^^^^^^^^^^^^^^^^^^^^^^^^
  File "/home/airflow/.local/lib/python3.12/site-packages/airflow/models/taskinstance.py", line 734, in _execute_callable
    return ExecutionCallableRunner(
           ^^^^^^^^^^^^^^^^^^^^^^^^
  File "/home/airflow/.local/lib/python3.12/site-packages/airflow/utils/operator_helpers.py", line 252, in run
    return self.func(*args, **kwargs)
           ^^^^^^^^^^^^^^^^^^^^^^^^^^
  File "/home/airflow/.local/lib/python3.12/site-packages/airflow/models/baseoperator.py", line 424, in wrapper
    return func(self, *args, **kwargs)
           ^^^^^^^^^^^^^^^^^^^^^^^^^^^
  File "/home/airflow/.local/lib/python3.12/site-packages/airflow/operators/bash.py", line 276, in execute
    raise AirflowException(
airflow.exceptions.AirflowException: Bash command failed. The command returned a non-zero exit code 2.
[2025-05-02T19:32:07.056+0000] {local_task_job_runner.py:266} INFO - Task exited with return code 1
[2025-05-02T19:32:07.106+0000] {taskinstance.py:3901} INFO - 0 downstream tasks scheduled from follow-on schedule check
[2025-05-02T19:32:07.129+0000] {standard_task_runner.py:217} INFO - Process not found (most likely exited), stop collecting metrics
[2025-05-02T19:32:07.134+0000] {local_task_job_runner.py:245} INFO - ::endgroup::
