[2025-05-03T13:23:23.430+0000] {local_task_job_runner.py:123} INFO - ::group::Pre task execution logs
[2025-05-03T13:23:23.472+0000] {taskinstance.py:2614} INFO - Dependencies all met for dep_context=non-requeueable deps ti=<TaskInstance: google_maps_reviews.export_to_csv manual__2025-05-03T13:20:54.258715+00:00 [queued]>
[2025-05-03T13:23:23.491+0000] {taskinstance.py:2614} INFO - Dependencies all met for dep_context=requeueable deps ti=<TaskInstance: google_maps_reviews.export_to_csv manual__2025-05-03T13:20:54.258715+00:00 [queued]>
[2025-05-03T13:23:23.510+0000] {taskinstance.py:2867} INFO - Starting attempt 1 of 2
[2025-05-03T13:23:23.535+0000] {taskinstance.py:2890} INFO - Executing <Task(PythonOperator): export_to_csv> on 2025-05-03 13:20:54.258715+00:00
[2025-05-03T13:23:23.551+0000] {warnings.py:112} WARNING - /home/***/.local/lib/python3.12/site-packages/***/task/task_runner/standard_task_runner.py:70: DeprecationWarning: This process (pid=3668) is multi-threaded, use of fork() may lead to deadlocks in the child.
  pid = os.fork()

[2025-05-03T13:23:23.555+0000] {standard_task_runner.py:72} INFO - Started process 3685 to run task
[2025-05-03T13:23:23.557+0000] {standard_task_runner.py:104} INFO - Running: ['***', 'tasks', 'run', 'google_maps_reviews', 'export_to_csv', 'manual__2025-05-03T13:20:54.258715+00:00', '--job-id', '294', '--raw', '--subdir', 'DAGS_FOLDER/***dag.py', '--cfg-path', '/tmp/tmpv2r_fiye']
[2025-05-03T13:23:23.561+0000] {standard_task_runner.py:105} INFO - Job 294: Subtask export_to_csv
[2025-05-03T13:23:23.647+0000] {task_command.py:467} INFO - Running <TaskInstance: google_maps_reviews.export_to_csv manual__2025-05-03T13:20:54.258715+00:00 [running]> on host 8280c28b7f0f
[2025-05-03T13:23:23.804+0000] {taskinstance.py:3134} INFO - Exporting env vars: AIRFLOW_CTX_DAG_OWNER='***' AIRFLOW_CTX_DAG_ID='google_maps_reviews' AIRFLOW_CTX_TASK_ID='export_to_csv' AIRFLOW_CTX_EXECUTION_DATE='2025-05-03T13:20:54.258715+00:00' AIRFLOW_CTX_TRY_NUMBER='1' AIRFLOW_CTX_DAG_RUN_ID='manual__2025-05-03T13:20:54.258715+00:00'
[2025-05-03T13:23:23.807+0000] {logging_mixin.py:190} INFO - Task instance is in running state
[2025-05-03T13:23:23.808+0000] {logging_mixin.py:190} INFO -  Previous state of the Task instance: queued
[2025-05-03T13:23:23.809+0000] {logging_mixin.py:190} INFO - Current task name:export_to_csv state:running start_date:2025-05-03 13:23:23.473912+00:00
[2025-05-03T13:23:23.810+0000] {logging_mixin.py:190} INFO - Dag name:google_maps_reviews and current dag run status:running
[2025-05-03T13:23:23.811+0000] {taskinstance.py:732} INFO - ::endgroup::
[2025-05-03T13:23:23.830+0000] {base.py:84} INFO - Retrieving connection 'postgres_defaut'
[2025-05-03T13:23:23.854+0000] {warnings.py:112} WARNING - /opt/***/dags/storeData.py:42: UserWarning: pandas only supports SQLAlchemy connectable (engine/connection) or database string URI or sqlite3 DBAPI2 connection. Other DBAPI2 objects are not tested. Please consider using SQLAlchemy.
  df = pd.read_sql_query(query, conn)

[2025-05-03T13:23:23.883+0000] {taskinstance.py:3313} ERROR - Task failed with exception
Traceback (most recent call last):
  File "/home/airflow/.local/lib/python3.12/site-packages/airflow/models/taskinstance.py", line 768, in _execute_task
    result = _execute_callable(context=context, **execute_callable_kwargs)
             ^^^^^^^^^^^^^^^^^^^^^^^^^^^^^^^^^^^^^^^^^^^^^^^^^^^^^^^^^^^^^
  File "/home/airflow/.local/lib/python3.12/site-packages/airflow/models/taskinstance.py", line 734, in _execute_callable
    return ExecutionCallableRunner(
           ^^^^^^^^^^^^^^^^^^^^^^^^
  File "/home/airflow/.local/lib/python3.12/site-packages/airflow/utils/operator_helpers.py", line 252, in run
    return self.func(*args, **kwargs)
           ^^^^^^^^^^^^^^^^^^^^^^^^^^
  File "/home/airflow/.local/lib/python3.12/site-packages/airflow/models/baseoperator.py", line 424, in wrapper
    return func(self, *args, **kwargs)
           ^^^^^^^^^^^^^^^^^^^^^^^^^^^
  File "/home/airflow/.local/lib/python3.12/site-packages/airflow/operators/python.py", line 238, in execute
    return_value = self.execute_callable()
                   ^^^^^^^^^^^^^^^^^^^^^^^
  File "/home/airflow/.local/lib/python3.12/site-packages/airflow/operators/python.py", line 256, in execute_callable
    return runner.run(*self.op_args, **self.op_kwargs)
           ^^^^^^^^^^^^^^^^^^^^^^^^^^^^^^^^^^^^^^^^^^^
  File "/home/airflow/.local/lib/python3.12/site-packages/airflow/utils/operator_helpers.py", line 252, in run
    return self.func(*args, **kwargs)
           ^^^^^^^^^^^^^^^^^^^^^^^^^^
  File "/opt/airflow/dags/storeData.py", line 51, in export_data
    df.to_csv(csv_path, index=False)
  File "/home/airflow/.local/lib/python3.12/site-packages/pandas/core/generic.py", line 3902, in to_csv
    return DataFrameRenderer(formatter).to_csv(
           ^^^^^^^^^^^^^^^^^^^^^^^^^^^^^^^^^^^^
  File "/home/airflow/.local/lib/python3.12/site-packages/pandas/io/formats/format.py", line 1152, in to_csv
    csv_formatter.save()
  File "/home/airflow/.local/lib/python3.12/site-packages/pandas/io/formats/csvs.py", line 247, in save
    with get_handle(
         ^^^^^^^^^^^
  File "/home/airflow/.local/lib/python3.12/site-packages/pandas/io/common.py", line 739, in get_handle
    check_parent_directory(str(handle))
  File "/home/airflow/.local/lib/python3.12/site-packages/pandas/io/common.py", line 604, in check_parent_directory
    raise OSError(rf"Cannot save file into a non-existent directory: '{parent}'")
OSError: Cannot save file into a non-existent directory: '/opt/***/dags/output'
[2025-05-03T13:23:23.915+0000] {logging_mixin.py:190} INFO - Task instance in failure state
[2025-05-03T13:23:23.916+0000] {logging_mixin.py:190} INFO - Task start:2025-05-03 13:23:23.473912+00:00 end:2025-05-03 13:23:23.914035+00:00 duration:0.440123
[2025-05-03T13:23:23.917+0000] {logging_mixin.py:190} INFO - Task:<Task(PythonOperator): export_to_csv> dag:<DAG: google_maps_reviews> dagrun:<DagRun google_maps_reviews @ 2025-05-03 13:20:54.258715+00:00: manual__2025-05-03T13:20:54.258715+00:00, state:running, queued_at: 2025-05-03 13:20:54.308778+00:00. externally triggered: True>
[2025-05-03T13:23:23.920+0000] {logging_mixin.py:190} INFO - Failure caused by Cannot save file into a non-existent directory: '/opt/***/dags/output'
[2025-05-03T13:23:23.922+0000] {taskinstance.py:1226} INFO - Marking task as UP_FOR_RETRY. dag_id=google_maps_reviews, task_id=export_to_csv, run_id=manual__2025-05-03T13:20:54.258715+00:00, execution_date=20250503T132054, start_date=20250503T132323, end_date=20250503T132323
[2025-05-03T13:23:24.006+0000] {taskinstance.py:341} INFO - ::group::Post task execution logs
[2025-05-03T13:23:24.009+0000] {standard_task_runner.py:124} ERROR - Failed to execute job 294 for task export_to_csv (Cannot save file into a non-existent directory: '/opt/***/dags/output'; 3685)
Traceback (most recent call last):
  File "/home/airflow/.local/lib/python3.12/site-packages/airflow/task/task_runner/standard_task_runner.py", line 117, in _start_by_fork
    ret = args.func(args, dag=self.dag)
          ^^^^^^^^^^^^^^^^^^^^^^^^^^^^^
  File "/home/airflow/.local/lib/python3.12/site-packages/airflow/cli/cli_config.py", line 49, in command
    return func(*args, **kwargs)
           ^^^^^^^^^^^^^^^^^^^^^
  File "/home/airflow/.local/lib/python3.12/site-packages/airflow/utils/cli.py", line 116, in wrapper
    return f(*args, **kwargs)
           ^^^^^^^^^^^^^^^^^^
  File "/home/airflow/.local/lib/python3.12/site-packages/airflow/cli/commands/task_command.py", line 483, in task_run
    task_return_code = _run_task_by_selected_method(args, _dag, ti)
                       ^^^^^^^^^^^^^^^^^^^^^^^^^^^^^^^^^^^^^^^^^^^^
  File "/home/airflow/.local/lib/python3.12/site-packages/airflow/cli/commands/task_command.py", line 256, in _run_task_by_selected_method
    return _run_raw_task(args, ti)
           ^^^^^^^^^^^^^^^^^^^^^^^
  File "/home/airflow/.local/lib/python3.12/site-packages/airflow/cli/commands/task_command.py", line 341, in _run_raw_task
    return ti._run_raw_task(
           ^^^^^^^^^^^^^^^^^
  File "/home/airflow/.local/lib/python3.12/site-packages/airflow/utils/session.py", line 97, in wrapper
    return func(*args, session=session, **kwargs)
           ^^^^^^^^^^^^^^^^^^^^^^^^^^^^^^^^^^^^^^
  File "/home/airflow/.local/lib/python3.12/site-packages/airflow/models/taskinstance.py", line 3006, in _run_raw_task
    return _run_raw_task(
           ^^^^^^^^^^^^^^
  File "/home/airflow/.local/lib/python3.12/site-packages/airflow/models/taskinstance.py", line 274, in _run_raw_task
    TaskInstance._execute_task_with_callbacks(
  File "/home/airflow/.local/lib/python3.12/site-packages/airflow/models/taskinstance.py", line 3161, in _execute_task_with_callbacks
    result = self._execute_task(context, task_orig)
             ^^^^^^^^^^^^^^^^^^^^^^^^^^^^^^^^^^^^^^
  File "/home/airflow/.local/lib/python3.12/site-packages/airflow/models/taskinstance.py", line 3185, in _execute_task
    return _execute_task(self, context, task_orig)
           ^^^^^^^^^^^^^^^^^^^^^^^^^^^^^^^^^^^^^^^
  File "/home/airflow/.local/lib/python3.12/site-packages/airflow/models/taskinstance.py", line 768, in _execute_task
    result = _execute_callable(context=context, **execute_callable_kwargs)
             ^^^^^^^^^^^^^^^^^^^^^^^^^^^^^^^^^^^^^^^^^^^^^^^^^^^^^^^^^^^^^
  File "/home/airflow/.local/lib/python3.12/site-packages/airflow/models/taskinstance.py", line 734, in _execute_callable
    return ExecutionCallableRunner(
           ^^^^^^^^^^^^^^^^^^^^^^^^
  File "/home/airflow/.local/lib/python3.12/site-packages/airflow/utils/operator_helpers.py", line 252, in run
    return self.func(*args, **kwargs)
           ^^^^^^^^^^^^^^^^^^^^^^^^^^
  File "/home/airflow/.local/lib/python3.12/site-packages/airflow/models/baseoperator.py", line 424, in wrapper
    return func(self, *args, **kwargs)
           ^^^^^^^^^^^^^^^^^^^^^^^^^^^
  File "/home/airflow/.local/lib/python3.12/site-packages/airflow/operators/python.py", line 238, in execute
    return_value = self.execute_callable()
                   ^^^^^^^^^^^^^^^^^^^^^^^
  File "/home/airflow/.local/lib/python3.12/site-packages/airflow/operators/python.py", line 256, in execute_callable
    return runner.run(*self.op_args, **self.op_kwargs)
           ^^^^^^^^^^^^^^^^^^^^^^^^^^^^^^^^^^^^^^^^^^^
  File "/home/airflow/.local/lib/python3.12/site-packages/airflow/utils/operator_helpers.py", line 252, in run
    return self.func(*args, **kwargs)
           ^^^^^^^^^^^^^^^^^^^^^^^^^^
  File "/opt/airflow/dags/storeData.py", line 51, in export_data
    df.to_csv(csv_path, index=False)
  File "/home/airflow/.local/lib/python3.12/site-packages/pandas/core/generic.py", line 3902, in to_csv
    return DataFrameRenderer(formatter).to_csv(
           ^^^^^^^^^^^^^^^^^^^^^^^^^^^^^^^^^^^^
  File "/home/airflow/.local/lib/python3.12/site-packages/pandas/io/formats/format.py", line 1152, in to_csv
    csv_formatter.save()
  File "/home/airflow/.local/lib/python3.12/site-packages/pandas/io/formats/csvs.py", line 247, in save
    with get_handle(
         ^^^^^^^^^^^
  File "/home/airflow/.local/lib/python3.12/site-packages/pandas/io/common.py", line 739, in get_handle
    check_parent_directory(str(handle))
  File "/home/airflow/.local/lib/python3.12/site-packages/pandas/io/common.py", line 604, in check_parent_directory
    raise OSError(rf"Cannot save file into a non-existent directory: '{parent}'")
OSError: Cannot save file into a non-existent directory: '/opt/***/dags/output'
[2025-05-03T13:23:24.057+0000] {local_task_job_runner.py:266} INFO - Task exited with return code 1
[2025-05-03T13:23:24.109+0000] {taskinstance.py:3901} INFO - 0 downstream tasks scheduled from follow-on schedule check
[2025-05-03T13:23:24.113+0000] {local_task_job_runner.py:245} INFO - ::endgroup::
