[2025-04-04T18:43:38.827+0000] {local_task_job_runner.py:123} INFO - ::group::Pre task execution logs
[2025-04-04T18:43:38.871+0000] {taskinstance.py:2614} INFO - Dependencies all met for dep_context=non-requeueable deps ti=<TaskInstance: google_maps_reviews_pipeline.Load_reviews1 manual__2025-04-04T18:43:20.593923+00:00 [queued]>
[2025-04-04T18:43:38.895+0000] {taskinstance.py:2614} INFO - Dependencies all met for dep_context=requeueable deps ti=<TaskInstance: google_maps_reviews_pipeline.Load_reviews1 manual__2025-04-04T18:43:20.593923+00:00 [queued]>
[2025-04-04T18:43:38.908+0000] {taskinstance.py:2867} INFO - Starting attempt 1 of 2
[2025-04-04T18:43:38.935+0000] {taskinstance.py:2890} INFO - Executing <Task(PythonOperator): Load_reviews1> on 2025-04-04 18:43:20.593923+00:00
[2025-04-04T18:43:38.951+0000] {warnings.py:112} WARNING - /home/***/.local/lib/python3.12/site-packages/***/task/task_runner/standard_task_runner.py:70: DeprecationWarning: This process (pid=199) is multi-threaded, use of fork() may lead to deadlocks in the child.
  pid = os.fork()

[2025-04-04T18:43:38.955+0000] {standard_task_runner.py:104} INFO - Running: ['***', 'tasks', 'run', 'google_maps_reviews_pipeline', 'Load_reviews1', 'manual__2025-04-04T18:43:20.593923+00:00', '--job-id', '13', '--raw', '--subdir', 'DAGS_FOLDER/***dag.py', '--cfg-path', '/tmp/tmp0dfn9p6q']
[2025-04-04T18:43:38.957+0000] {standard_task_runner.py:72} INFO - Started process 214 to run task
[2025-04-04T18:43:38.958+0000] {standard_task_runner.py:105} INFO - Job 13: Subtask Load_reviews1
[2025-04-04T18:43:39.055+0000] {task_command.py:467} INFO - Running <TaskInstance: google_maps_reviews_pipeline.Load_reviews1 manual__2025-04-04T18:43:20.593923+00:00 [running]> on host c3eecb2684dd
[2025-04-04T18:43:39.236+0000] {taskinstance.py:3134} INFO - Exporting env vars: AIRFLOW_CTX_DAG_OWNER='***' AIRFLOW_CTX_DAG_ID='google_maps_reviews_pipeline' AIRFLOW_CTX_TASK_ID='Load_reviews1' AIRFLOW_CTX_EXECUTION_DATE='2025-04-04T18:43:20.593923+00:00' AIRFLOW_CTX_TRY_NUMBER='1' AIRFLOW_CTX_DAG_RUN_ID='manual__2025-04-04T18:43:20.593923+00:00'
[2025-04-04T18:43:39.240+0000] {logging_mixin.py:190} INFO - Task instance is in running state
[2025-04-04T18:43:39.241+0000] {logging_mixin.py:190} INFO -  Previous state of the Task instance: queued
[2025-04-04T18:43:39.243+0000] {logging_mixin.py:190} INFO - Current task name:Load_reviews1 state:running start_date:2025-04-04 18:43:38.874043+00:00
[2025-04-04T18:43:39.244+0000] {logging_mixin.py:190} INFO - Dag name:google_maps_reviews_pipeline and current dag run status:running
[2025-04-04T18:43:39.245+0000] {taskinstance.py:732} INFO - ::endgroup::
[2025-04-04T18:43:39.286+0000] {logging_mixin.py:190} INFO - Current directory: /opt/***/dags
[2025-04-04T18:43:39.287+0000] {logging_mixin.py:190} INFO - Data path: /opt/***/dags/input/reviews.csv
[2025-04-04T18:43:39.353+0000] {taskinstance.py:3313} ERROR - Task failed with exception
Traceback (most recent call last):
  File "/home/airflow/.local/lib/python3.12/site-packages/airflow/models/taskinstance.py", line 768, in _execute_task
    result = _execute_callable(context=context, **execute_callable_kwargs)
             ^^^^^^^^^^^^^^^^^^^^^^^^^^^^^^^^^^^^^^^^^^^^^^^^^^^^^^^^^^^^^
  File "/home/airflow/.local/lib/python3.12/site-packages/airflow/models/taskinstance.py", line 734, in _execute_callable
    return ExecutionCallableRunner(
           ^^^^^^^^^^^^^^^^^^^^^^^^
  File "/home/airflow/.local/lib/python3.12/site-packages/airflow/utils/operator_helpers.py", line 252, in run
    return self.func(*args, **kwargs)
           ^^^^^^^^^^^^^^^^^^^^^^^^^^
  File "/home/airflow/.local/lib/python3.12/site-packages/airflow/models/baseoperator.py", line 424, in wrapper
    return func(self, *args, **kwargs)
           ^^^^^^^^^^^^^^^^^^^^^^^^^^^
  File "/home/airflow/.local/lib/python3.12/site-packages/airflow/operators/python.py", line 238, in execute
    return_value = self.execute_callable()
                   ^^^^^^^^^^^^^^^^^^^^^^^
  File "/home/airflow/.local/lib/python3.12/site-packages/airflow/operators/python.py", line 256, in execute_callable
    return runner.run(*self.op_args, **self.op_kwargs)
           ^^^^^^^^^^^^^^^^^^^^^^^^^^^^^^^^^^^^^^^^^^^
  File "/home/airflow/.local/lib/python3.12/site-packages/airflow/utils/operator_helpers.py", line 252, in run
    return self.func(*args, **kwargs)
           ^^^^^^^^^^^^^^^^^^^^^^^^^^
  File "/opt/airflow/dags/storeData.py", line 271, in Load_reviews1
    conn = pg_hook.get_conn()
           ^^^^^^^^^^^^^^^^^^
  File "/home/airflow/.local/lib/python3.12/site-packages/airflow/providers/postgres/hooks/postgres.py", line 141, in get_conn
    conn = deepcopy(self.connection)
                    ^^^^^^^^^^^^^^^
  File "/home/airflow/.local/lib/python3.12/site-packages/airflow/providers/common/sql/hooks/sql.py", line 180, in connection
    self._connection = self.get_connection(self.get_conn_id())
                       ^^^^^^^^^^^^^^^^^^^^^^^^^^^^^^^^^^^^^^^
  File "/home/airflow/.local/lib/python3.12/site-packages/airflow/hooks/base.py", line 83, in get_connection
    conn = Connection.get_connection_from_secrets(conn_id)
           ^^^^^^^^^^^^^^^^^^^^^^^^^^^^^^^^^^^^^^^^^^^^^^^
  File "/home/airflow/.local/lib/python3.12/site-packages/airflow/models/connection.py", line 537, in get_connection_from_secrets
    raise AirflowNotFoundException(f"The conn_id `{conn_id}` isn't defined")
airflow.exceptions.AirflowNotFoundException: The conn_id `postgres_defaut` isn't defined
[2025-04-04T18:43:39.380+0000] {logging_mixin.py:190} INFO - Task instance in failure state
[2025-04-04T18:43:39.381+0000] {logging_mixin.py:190} INFO - Task start:2025-04-04 18:43:38.874043+00:00 end:2025-04-04 18:43:39.378628+00:00 duration:0.504585
[2025-04-04T18:43:39.382+0000] {logging_mixin.py:190} INFO - Task:<Task(PythonOperator): Load_reviews1> dag:<DAG: google_maps_reviews_pipeline> dagrun:<DagRun google_maps_reviews_pipeline @ 2025-04-04 18:43:20.593923+00:00: manual__2025-04-04T18:43:20.593923+00:00, state:running, queued_at: 2025-04-04 18:43:20.618851+00:00. externally triggered: True>
[2025-04-04T18:43:39.383+0000] {logging_mixin.py:190} INFO - Failure caused by The conn_id `postgres_defaut` isn't defined
[2025-04-04T18:43:39.384+0000] {taskinstance.py:1226} INFO - Marking task as UP_FOR_RETRY. dag_id=google_maps_reviews_pipeline, task_id=Load_reviews1, run_id=manual__2025-04-04T18:43:20.593923+00:00, execution_date=20250404T184320, start_date=20250404T184338, end_date=20250404T184339
[2025-04-04T18:43:39.447+0000] {taskinstance.py:341} INFO - ::group::Post task execution logs
[2025-04-04T18:43:39.449+0000] {standard_task_runner.py:124} ERROR - Failed to execute job 13 for task Load_reviews1 (The conn_id `postgres_defaut` isn't defined; 214)
Traceback (most recent call last):
  File "/home/airflow/.local/lib/python3.12/site-packages/airflow/task/task_runner/standard_task_runner.py", line 117, in _start_by_fork
    ret = args.func(args, dag=self.dag)
          ^^^^^^^^^^^^^^^^^^^^^^^^^^^^^
  File "/home/airflow/.local/lib/python3.12/site-packages/airflow/cli/cli_config.py", line 49, in command
    return func(*args, **kwargs)
           ^^^^^^^^^^^^^^^^^^^^^
  File "/home/airflow/.local/lib/python3.12/site-packages/airflow/utils/cli.py", line 116, in wrapper
    return f(*args, **kwargs)
           ^^^^^^^^^^^^^^^^^^
  File "/home/airflow/.local/lib/python3.12/site-packages/airflow/cli/commands/task_command.py", line 483, in task_run
    task_return_code = _run_task_by_selected_method(args, _dag, ti)
                       ^^^^^^^^^^^^^^^^^^^^^^^^^^^^^^^^^^^^^^^^^^^^
  File "/home/airflow/.local/lib/python3.12/site-packages/airflow/cli/commands/task_command.py", line 256, in _run_task_by_selected_method
    return _run_raw_task(args, ti)
           ^^^^^^^^^^^^^^^^^^^^^^^
  File "/home/airflow/.local/lib/python3.12/site-packages/airflow/cli/commands/task_command.py", line 341, in _run_raw_task
    return ti._run_raw_task(
           ^^^^^^^^^^^^^^^^^
  File "/home/airflow/.local/lib/python3.12/site-packages/airflow/utils/session.py", line 97, in wrapper
    return func(*args, session=session, **kwargs)
           ^^^^^^^^^^^^^^^^^^^^^^^^^^^^^^^^^^^^^^
  File "/home/airflow/.local/lib/python3.12/site-packages/airflow/models/taskinstance.py", line 3006, in _run_raw_task
    return _run_raw_task(
           ^^^^^^^^^^^^^^
  File "/home/airflow/.local/lib/python3.12/site-packages/airflow/models/taskinstance.py", line 274, in _run_raw_task
    TaskInstance._execute_task_with_callbacks(
  File "/home/airflow/.local/lib/python3.12/site-packages/airflow/models/taskinstance.py", line 3161, in _execute_task_with_callbacks
    result = self._execute_task(context, task_orig)
             ^^^^^^^^^^^^^^^^^^^^^^^^^^^^^^^^^^^^^^
  File "/home/airflow/.local/lib/python3.12/site-packages/airflow/models/taskinstance.py", line 3185, in _execute_task
    return _execute_task(self, context, task_orig)
           ^^^^^^^^^^^^^^^^^^^^^^^^^^^^^^^^^^^^^^^
  File "/home/airflow/.local/lib/python3.12/site-packages/airflow/models/taskinstance.py", line 768, in _execute_task
    result = _execute_callable(context=context, **execute_callable_kwargs)
             ^^^^^^^^^^^^^^^^^^^^^^^^^^^^^^^^^^^^^^^^^^^^^^^^^^^^^^^^^^^^^
  File "/home/airflow/.local/lib/python3.12/site-packages/airflow/models/taskinstance.py", line 734, in _execute_callable
    return ExecutionCallableRunner(
           ^^^^^^^^^^^^^^^^^^^^^^^^
  File "/home/airflow/.local/lib/python3.12/site-packages/airflow/utils/operator_helpers.py", line 252, in run
    return self.func(*args, **kwargs)
           ^^^^^^^^^^^^^^^^^^^^^^^^^^
  File "/home/airflow/.local/lib/python3.12/site-packages/airflow/models/baseoperator.py", line 424, in wrapper
    return func(self, *args, **kwargs)
           ^^^^^^^^^^^^^^^^^^^^^^^^^^^
  File "/home/airflow/.local/lib/python3.12/site-packages/airflow/operators/python.py", line 238, in execute
    return_value = self.execute_callable()
                   ^^^^^^^^^^^^^^^^^^^^^^^
  File "/home/airflow/.local/lib/python3.12/site-packages/airflow/operators/python.py", line 256, in execute_callable
    return runner.run(*self.op_args, **self.op_kwargs)
           ^^^^^^^^^^^^^^^^^^^^^^^^^^^^^^^^^^^^^^^^^^^
  File "/home/airflow/.local/lib/python3.12/site-packages/airflow/utils/operator_helpers.py", line 252, in run
    return self.func(*args, **kwargs)
           ^^^^^^^^^^^^^^^^^^^^^^^^^^
  File "/opt/airflow/dags/storeData.py", line 271, in Load_reviews1
    conn = pg_hook.get_conn()
           ^^^^^^^^^^^^^^^^^^
  File "/home/airflow/.local/lib/python3.12/site-packages/airflow/providers/postgres/hooks/postgres.py", line 141, in get_conn
    conn = deepcopy(self.connection)
                    ^^^^^^^^^^^^^^^
  File "/home/airflow/.local/lib/python3.12/site-packages/airflow/providers/common/sql/hooks/sql.py", line 180, in connection
    self._connection = self.get_connection(self.get_conn_id())
                       ^^^^^^^^^^^^^^^^^^^^^^^^^^^^^^^^^^^^^^^
  File "/home/airflow/.local/lib/python3.12/site-packages/airflow/hooks/base.py", line 83, in get_connection
    conn = Connection.get_connection_from_secrets(conn_id)
           ^^^^^^^^^^^^^^^^^^^^^^^^^^^^^^^^^^^^^^^^^^^^^^^
  File "/home/airflow/.local/lib/python3.12/site-packages/airflow/models/connection.py", line 537, in get_connection_from_secrets
    raise AirflowNotFoundException(f"The conn_id `{conn_id}` isn't defined")
airflow.exceptions.AirflowNotFoundException: The conn_id `postgres_defaut` isn't defined
[2025-04-04T18:43:39.499+0000] {local_task_job_runner.py:266} INFO - Task exited with return code 1
[2025-04-04T18:43:39.553+0000] {taskinstance.py:3901} INFO - 0 downstream tasks scheduled from follow-on schedule check
[2025-04-04T18:43:39.560+0000] {local_task_job_runner.py:245} INFO - ::endgroup::
