[2025-05-06T21:00:15.042+0000] {local_task_job_runner.py:123} INFO - ::group::Pre task execution logs
[2025-05-06T21:00:15.062+0000] {taskinstance.py:2614} INFO - Dependencies all met for dep_context=non-requeueable deps ti=<TaskInstance: google_maps_reviews.normalize_and_clean_data manual__2025-05-06T20:00:25.137792+00:00 [queued]>
[2025-05-06T21:00:15.072+0000] {taskinstance.py:2614} INFO - Dependencies all met for dep_context=requeueable deps ti=<TaskInstance: google_maps_reviews.normalize_and_clean_data manual__2025-05-06T20:00:25.137792+00:00 [queued]>
[2025-05-06T21:00:15.073+0000] {taskinstance.py:2867} INFO - Starting attempt 10 of 11
[2025-05-06T21:00:15.085+0000] {taskinstance.py:2890} INFO - Executing <Task(PythonOperator): normalize_and_clean_data> on 2025-05-06 20:00:25.137792+00:00
[2025-05-06T21:00:15.096+0000] {warnings.py:112} WARNING - /home/***/.local/lib/python3.12/site-packages/***/task/task_runner/standard_task_runner.py:70: DeprecationWarning: This process (pid=8683) is multi-threaded, use of fork() may lead to deadlocks in the child.
  pid = os.fork()

[2025-05-06T21:00:15.099+0000] {standard_task_runner.py:104} INFO - Running: ['***', 'tasks', 'run', 'google_maps_reviews', 'normalize_and_clean_data', 'manual__2025-05-06T20:00:25.137792+00:00', '--job-id', '645', '--raw', '--subdir', 'DAGS_FOLDER/***dag.py', '--cfg-path', '/tmp/tmp18lc8fdd']
[2025-05-06T21:00:15.100+0000] {standard_task_runner.py:72} INFO - Started process 8698 to run task
[2025-05-06T21:00:15.100+0000] {standard_task_runner.py:105} INFO - Job 645: Subtask normalize_and_clean_data
[2025-05-06T21:00:15.144+0000] {task_command.py:467} INFO - Running <TaskInstance: google_maps_reviews.normalize_and_clean_data manual__2025-05-06T20:00:25.137792+00:00 [running]> on host 8280c28b7f0f
[2025-05-06T21:00:15.222+0000] {taskinstance.py:3134} INFO - Exporting env vars: AIRFLOW_CTX_DAG_OWNER='***' AIRFLOW_CTX_DAG_ID='google_maps_reviews' AIRFLOW_CTX_TASK_ID='normalize_and_clean_data' AIRFLOW_CTX_EXECUTION_DATE='2025-05-06T20:00:25.137792+00:00' AIRFLOW_CTX_TRY_NUMBER='10' AIRFLOW_CTX_DAG_RUN_ID='manual__2025-05-06T20:00:25.137792+00:00'
[2025-05-06T21:00:15.223+0000] {logging_mixin.py:190} INFO - Task instance is in running state
[2025-05-06T21:00:15.224+0000] {logging_mixin.py:190} INFO -  Previous state of the Task instance: queued
[2025-05-06T21:00:15.224+0000] {logging_mixin.py:190} INFO - Current task name:normalize_and_clean_data state:running start_date:2025-05-06 21:00:15.062745+00:00
[2025-05-06T21:00:15.225+0000] {logging_mixin.py:190} INFO - Dag name:google_maps_reviews and current dag run status:running
[2025-05-06T21:00:15.225+0000] {taskinstance.py:732} INFO - ::endgroup::
[2025-05-06T21:00:15.233+0000] {base.py:84} INFO - Retrieving connection 'postgres_defaut'
[2025-05-06T21:00:15.241+0000] {warnings.py:112} WARNING - /opt/***/dags/storeData.py:315: UserWarning: pandas only supports SQLAlchemy connectable (engine/connection) or database string URI or sqlite3 DBAPI2 connection. Other DBAPI2 objects are not tested. Please consider using SQLAlchemy.
  df = pd.read_sql("SELECT * FROM review.raw_reviews", conn)

[2025-05-06T21:00:15.286+0000] {taskinstance.py:3313} ERROR - Task failed with exception
Traceback (most recent call last):
  File "/home/airflow/.local/lib/python3.12/site-packages/airflow/models/taskinstance.py", line 768, in _execute_task
    result = _execute_callable(context=context, **execute_callable_kwargs)
             ^^^^^^^^^^^^^^^^^^^^^^^^^^^^^^^^^^^^^^^^^^^^^^^^^^^^^^^^^^^^^
  File "/home/airflow/.local/lib/python3.12/site-packages/airflow/models/taskinstance.py", line 734, in _execute_callable
    return ExecutionCallableRunner(
           ^^^^^^^^^^^^^^^^^^^^^^^^
  File "/home/airflow/.local/lib/python3.12/site-packages/airflow/utils/operator_helpers.py", line 252, in run
    return self.func(*args, **kwargs)
           ^^^^^^^^^^^^^^^^^^^^^^^^^^
  File "/home/airflow/.local/lib/python3.12/site-packages/airflow/models/baseoperator.py", line 424, in wrapper
    return func(self, *args, **kwargs)
           ^^^^^^^^^^^^^^^^^^^^^^^^^^^
  File "/home/airflow/.local/lib/python3.12/site-packages/airflow/operators/python.py", line 238, in execute
    return_value = self.execute_callable()
                   ^^^^^^^^^^^^^^^^^^^^^^^
  File "/home/airflow/.local/lib/python3.12/site-packages/airflow/operators/python.py", line 256, in execute_callable
    return runner.run(*self.op_args, **self.op_kwargs)
           ^^^^^^^^^^^^^^^^^^^^^^^^^^^^^^^^^^^^^^^^^^^
  File "/home/airflow/.local/lib/python3.12/site-packages/airflow/utils/operator_helpers.py", line 252, in run
    return self.func(*args, **kwargs)
           ^^^^^^^^^^^^^^^^^^^^^^^^^^
  File "/opt/airflow/dags/storeData.py", line 334, in normalize_and_clean_data
    cur.execute("""
psycopg2.errors.SyntaxError: syntax error at or near "ON"
LINE 6:                      ON CONFLICT ON CONSTRAINT unique_review...
                             ^

[2025-05-06T21:00:15.300+0000] {logging_mixin.py:190} INFO - Task instance in failure state
[2025-05-06T21:00:15.301+0000] {logging_mixin.py:190} INFO - Task start:2025-05-06 21:00:15.062745+00:00 end:2025-05-06 21:00:15.300341+00:00 duration:0.237596
[2025-05-06T21:00:15.302+0000] {logging_mixin.py:190} INFO - Task:<Task(PythonOperator): normalize_and_clean_data> dag:<DAG: google_maps_reviews> dagrun:<DagRun google_maps_reviews @ 2025-05-06 20:00:25.137792+00:00: manual__2025-05-06T20:00:25.137792+00:00, state:running, queued_at: 2025-05-06 20:53:50.086901+00:00. externally triggered: True>
[2025-05-06T21:00:15.303+0000] {logging_mixin.py:190} INFO - Failure caused by syntax error at or near "ON"
LINE 6:                      ON CONFLICT ON CONSTRAINT unique_review...
                             ^
[2025-05-06T21:00:15.304+0000] {taskinstance.py:1226} INFO - Marking task as UP_FOR_RETRY. dag_id=google_maps_reviews, task_id=normalize_and_clean_data, run_id=manual__2025-05-06T20:00:25.137792+00:00, execution_date=20250506T200025, start_date=20250506T210015, end_date=20250506T210015
[2025-05-06T21:00:15.338+0000] {taskinstance.py:341} INFO - ::group::Post task execution logs
[2025-05-06T21:00:15.339+0000] {standard_task_runner.py:124} ERROR - Failed to execute job 645 for task normalize_and_clean_data (syntax error at or near "ON"
LINE 6:                      ON CONFLICT ON CONSTRAINT unique_review...
                             ^
; 8698)
Traceback (most recent call last):
  File "/home/airflow/.local/lib/python3.12/site-packages/airflow/task/task_runner/standard_task_runner.py", line 117, in _start_by_fork
    ret = args.func(args, dag=self.dag)
          ^^^^^^^^^^^^^^^^^^^^^^^^^^^^^
  File "/home/airflow/.local/lib/python3.12/site-packages/airflow/cli/cli_config.py", line 49, in command
    return func(*args, **kwargs)
           ^^^^^^^^^^^^^^^^^^^^^
  File "/home/airflow/.local/lib/python3.12/site-packages/airflow/utils/cli.py", line 116, in wrapper
    return f(*args, **kwargs)
           ^^^^^^^^^^^^^^^^^^
  File "/home/airflow/.local/lib/python3.12/site-packages/airflow/cli/commands/task_command.py", line 483, in task_run
    task_return_code = _run_task_by_selected_method(args, _dag, ti)
                       ^^^^^^^^^^^^^^^^^^^^^^^^^^^^^^^^^^^^^^^^^^^^
  File "/home/airflow/.local/lib/python3.12/site-packages/airflow/cli/commands/task_command.py", line 256, in _run_task_by_selected_method
    return _run_raw_task(args, ti)
           ^^^^^^^^^^^^^^^^^^^^^^^
  File "/home/airflow/.local/lib/python3.12/site-packages/airflow/cli/commands/task_command.py", line 341, in _run_raw_task
    return ti._run_raw_task(
           ^^^^^^^^^^^^^^^^^
  File "/home/airflow/.local/lib/python3.12/site-packages/airflow/utils/session.py", line 97, in wrapper
    return func(*args, session=session, **kwargs)
           ^^^^^^^^^^^^^^^^^^^^^^^^^^^^^^^^^^^^^^
  File "/home/airflow/.local/lib/python3.12/site-packages/airflow/models/taskinstance.py", line 3006, in _run_raw_task
    return _run_raw_task(
           ^^^^^^^^^^^^^^
  File "/home/airflow/.local/lib/python3.12/site-packages/airflow/models/taskinstance.py", line 274, in _run_raw_task
    TaskInstance._execute_task_with_callbacks(
  File "/home/airflow/.local/lib/python3.12/site-packages/airflow/models/taskinstance.py", line 3161, in _execute_task_with_callbacks
    result = self._execute_task(context, task_orig)
             ^^^^^^^^^^^^^^^^^^^^^^^^^^^^^^^^^^^^^^
  File "/home/airflow/.local/lib/python3.12/site-packages/airflow/models/taskinstance.py", line 3185, in _execute_task
    return _execute_task(self, context, task_orig)
           ^^^^^^^^^^^^^^^^^^^^^^^^^^^^^^^^^^^^^^^
  File "/home/airflow/.local/lib/python3.12/site-packages/airflow/models/taskinstance.py", line 768, in _execute_task
    result = _execute_callable(context=context, **execute_callable_kwargs)
             ^^^^^^^^^^^^^^^^^^^^^^^^^^^^^^^^^^^^^^^^^^^^^^^^^^^^^^^^^^^^^
  File "/home/airflow/.local/lib/python3.12/site-packages/airflow/models/taskinstance.py", line 734, in _execute_callable
    return ExecutionCallableRunner(
           ^^^^^^^^^^^^^^^^^^^^^^^^
  File "/home/airflow/.local/lib/python3.12/site-packages/airflow/utils/operator_helpers.py", line 252, in run
    return self.func(*args, **kwargs)
           ^^^^^^^^^^^^^^^^^^^^^^^^^^
  File "/home/airflow/.local/lib/python3.12/site-packages/airflow/models/baseoperator.py", line 424, in wrapper
    return func(self, *args, **kwargs)
           ^^^^^^^^^^^^^^^^^^^^^^^^^^^
  File "/home/airflow/.local/lib/python3.12/site-packages/airflow/operators/python.py", line 238, in execute
    return_value = self.execute_callable()
                   ^^^^^^^^^^^^^^^^^^^^^^^
  File "/home/airflow/.local/lib/python3.12/site-packages/airflow/operators/python.py", line 256, in execute_callable
    return runner.run(*self.op_args, **self.op_kwargs)
           ^^^^^^^^^^^^^^^^^^^^^^^^^^^^^^^^^^^^^^^^^^^
  File "/home/airflow/.local/lib/python3.12/site-packages/airflow/utils/operator_helpers.py", line 252, in run
    return self.func(*args, **kwargs)
           ^^^^^^^^^^^^^^^^^^^^^^^^^^
  File "/opt/airflow/dags/storeData.py", line 334, in normalize_and_clean_data
    cur.execute("""
psycopg2.errors.SyntaxError: syntax error at or near "ON"
LINE 6:                      ON CONFLICT ON CONSTRAINT unique_review...
                             ^

[2025-05-06T21:00:15.358+0000] {local_task_job_runner.py:266} INFO - Task exited with return code 1
[2025-05-06T21:00:15.390+0000] {taskinstance.py:3901} INFO - 0 downstream tasks scheduled from follow-on schedule check
[2025-05-06T21:00:15.392+0000] {local_task_job_runner.py:245} INFO - ::endgroup::
