[2025-05-07T00:08:29.874+0000] {local_task_job_runner.py:123} INFO - ::group::Pre task execution logs
[2025-05-07T00:08:29.922+0000] {taskinstance.py:2614} INFO - Dependencies all met for dep_context=non-requeueable deps ti=<TaskInstance: google_maps_reviews.model_data scheduled__2025-05-06T00:00:00+00:00 [queued]>
[2025-05-07T00:08:29.946+0000] {taskinstance.py:2614} INFO - Dependencies all met for dep_context=requeueable deps ti=<TaskInstance: google_maps_reviews.model_data scheduled__2025-05-06T00:00:00+00:00 [queued]>
[2025-05-07T00:08:29.948+0000] {taskinstance.py:2867} INFO - Starting attempt 2 of 2
[2025-05-07T00:08:29.979+0000] {taskinstance.py:2890} INFO - Executing <Task(PythonOperator): model_data> on 2025-05-06 00:00:00+00:00
[2025-05-07T00:08:30.003+0000] {warnings.py:112} WARNING - /home/***/.local/lib/python3.12/site-packages/***/task/task_runner/standard_task_runner.py:70: DeprecationWarning: This process (pid=10432) is multi-threaded, use of fork() may lead to deadlocks in the child.
  pid = os.fork()

[2025-05-07T00:08:30.007+0000] {standard_task_runner.py:72} INFO - Started process 10447 to run task
[2025-05-07T00:08:30.013+0000] {standard_task_runner.py:104} INFO - Running: ['***', 'tasks', 'run', 'google_maps_reviews', 'model_data', 'scheduled__2025-05-06T00:00:00+00:00', '--job-id', '675', '--raw', '--subdir', 'DAGS_FOLDER/***dag.py', '--cfg-path', '/tmp/tmpob04yv3e']
[2025-05-07T00:08:30.016+0000] {standard_task_runner.py:105} INFO - Job 675: Subtask model_data
[2025-05-07T00:08:30.120+0000] {task_command.py:467} INFO - Running <TaskInstance: google_maps_reviews.model_data scheduled__2025-05-06T00:00:00+00:00 [running]> on host 8280c28b7f0f
[2025-05-07T00:08:30.299+0000] {taskinstance.py:3134} INFO - Exporting env vars: AIRFLOW_CTX_DAG_OWNER='***' AIRFLOW_CTX_DAG_ID='google_maps_reviews' AIRFLOW_CTX_TASK_ID='model_data' AIRFLOW_CTX_EXECUTION_DATE='2025-05-06T00:00:00+00:00' AIRFLOW_CTX_TRY_NUMBER='2' AIRFLOW_CTX_DAG_RUN_ID='scheduled__2025-05-06T00:00:00+00:00'
[2025-05-07T00:08:30.302+0000] {logging_mixin.py:190} INFO - Task instance is in running state
[2025-05-07T00:08:30.303+0000] {logging_mixin.py:190} INFO -  Previous state of the Task instance: queued
[2025-05-07T00:08:30.304+0000] {logging_mixin.py:190} INFO - Current task name:model_data state:running start_date:2025-05-07 00:08:29.924254+00:00
[2025-05-07T00:08:30.305+0000] {logging_mixin.py:190} INFO - Dag name:google_maps_reviews and current dag run status:running
[2025-05-07T00:08:30.306+0000] {taskinstance.py:732} INFO - ::endgroup::
[2025-05-07T00:08:30.321+0000] {base.py:84} INFO - Retrieving connection 'postgres_defaut'
[2025-05-07T00:08:30.332+0000] {taskinstance.py:3313} ERROR - Task failed with exception
Traceback (most recent call last):
  File "/home/airflow/.local/lib/python3.12/site-packages/airflow/models/taskinstance.py", line 768, in _execute_task
    result = _execute_callable(context=context, **execute_callable_kwargs)
             ^^^^^^^^^^^^^^^^^^^^^^^^^^^^^^^^^^^^^^^^^^^^^^^^^^^^^^^^^^^^^
  File "/home/airflow/.local/lib/python3.12/site-packages/airflow/models/taskinstance.py", line 734, in _execute_callable
    return ExecutionCallableRunner(
           ^^^^^^^^^^^^^^^^^^^^^^^^
  File "/home/airflow/.local/lib/python3.12/site-packages/airflow/utils/operator_helpers.py", line 252, in run
    return self.func(*args, **kwargs)
           ^^^^^^^^^^^^^^^^^^^^^^^^^^
  File "/home/airflow/.local/lib/python3.12/site-packages/airflow/models/baseoperator.py", line 424, in wrapper
    return func(self, *args, **kwargs)
           ^^^^^^^^^^^^^^^^^^^^^^^^^^^
  File "/home/airflow/.local/lib/python3.12/site-packages/airflow/operators/python.py", line 238, in execute
    return_value = self.execute_callable()
                   ^^^^^^^^^^^^^^^^^^^^^^^
  File "/home/airflow/.local/lib/python3.12/site-packages/airflow/operators/python.py", line 256, in execute_callable
    return runner.run(*self.op_args, **self.op_kwargs)
           ^^^^^^^^^^^^^^^^^^^^^^^^^^^^^^^^^^^^^^^^^^^
  File "/home/airflow/.local/lib/python3.12/site-packages/airflow/utils/operator_helpers.py", line 252, in run
    return self.func(*args, **kwargs)
           ^^^^^^^^^^^^^^^^^^^^^^^^^^
  File "/opt/airflow/dags/storeData.py", line 217, in model_data
    raise e
  File "/opt/airflow/dags/storeData.py", line 212, in model_data
    cur.execute(populate_dim_sql)
psycopg2.errors.InvalidColumnReference: there is no unique or exclusion constraint matching the ON CONFLICT specification

[2025-05-07T00:08:30.358+0000] {logging_mixin.py:190} INFO - Task instance in failure state
[2025-05-07T00:08:30.361+0000] {logging_mixin.py:190} INFO - Task start:2025-05-07 00:08:29.924254+00:00 end:2025-05-07 00:08:30.357263+00:00 duration:0.433009
[2025-05-07T00:08:30.363+0000] {logging_mixin.py:190} INFO - Task:<Task(PythonOperator): model_data> dag:<DAG: google_maps_reviews> dagrun:<DagRun google_maps_reviews @ 2025-05-06 00:00:00+00:00: scheduled__2025-05-06T00:00:00+00:00, state:running, queued_at: 2025-05-07 00:00:00.040155+00:00. externally triggered: False>
[2025-05-07T00:08:30.364+0000] {logging_mixin.py:190} INFO - Failure caused by there is no unique or exclusion constraint matching the ON CONFLICT specification
[2025-05-07T00:08:30.365+0000] {taskinstance.py:1226} INFO - Marking task as FAILED. dag_id=google_maps_reviews, task_id=model_data, run_id=scheduled__2025-05-06T00:00:00+00:00, execution_date=20250506T000000, start_date=20250507T000829, end_date=20250507T000830
[2025-05-07T00:08:30.422+0000] {taskinstance.py:341} INFO - ::group::Post task execution logs
[2025-05-07T00:08:30.428+0000] {standard_task_runner.py:124} ERROR - Failed to execute job 675 for task model_data (there is no unique or exclusion constraint matching the ON CONFLICT specification
; 10447)
Traceback (most recent call last):
  File "/home/airflow/.local/lib/python3.12/site-packages/airflow/task/task_runner/standard_task_runner.py", line 117, in _start_by_fork
    ret = args.func(args, dag=self.dag)
          ^^^^^^^^^^^^^^^^^^^^^^^^^^^^^
  File "/home/airflow/.local/lib/python3.12/site-packages/airflow/cli/cli_config.py", line 49, in command
    return func(*args, **kwargs)
           ^^^^^^^^^^^^^^^^^^^^^
  File "/home/airflow/.local/lib/python3.12/site-packages/airflow/utils/cli.py", line 116, in wrapper
    return f(*args, **kwargs)
           ^^^^^^^^^^^^^^^^^^
  File "/home/airflow/.local/lib/python3.12/site-packages/airflow/cli/commands/task_command.py", line 483, in task_run
    task_return_code = _run_task_by_selected_method(args, _dag, ti)
                       ^^^^^^^^^^^^^^^^^^^^^^^^^^^^^^^^^^^^^^^^^^^^
  File "/home/airflow/.local/lib/python3.12/site-packages/airflow/cli/commands/task_command.py", line 256, in _run_task_by_selected_method
    return _run_raw_task(args, ti)
           ^^^^^^^^^^^^^^^^^^^^^^^
  File "/home/airflow/.local/lib/python3.12/site-packages/airflow/cli/commands/task_command.py", line 341, in _run_raw_task
    return ti._run_raw_task(
           ^^^^^^^^^^^^^^^^^
  File "/home/airflow/.local/lib/python3.12/site-packages/airflow/utils/session.py", line 97, in wrapper
    return func(*args, session=session, **kwargs)
           ^^^^^^^^^^^^^^^^^^^^^^^^^^^^^^^^^^^^^^
  File "/home/airflow/.local/lib/python3.12/site-packages/airflow/models/taskinstance.py", line 3006, in _run_raw_task
    return _run_raw_task(
           ^^^^^^^^^^^^^^
  File "/home/airflow/.local/lib/python3.12/site-packages/airflow/models/taskinstance.py", line 274, in _run_raw_task
    TaskInstance._execute_task_with_callbacks(
  File "/home/airflow/.local/lib/python3.12/site-packages/airflow/models/taskinstance.py", line 3161, in _execute_task_with_callbacks
    result = self._execute_task(context, task_orig)
             ^^^^^^^^^^^^^^^^^^^^^^^^^^^^^^^^^^^^^^
  File "/home/airflow/.local/lib/python3.12/site-packages/airflow/models/taskinstance.py", line 3185, in _execute_task
    return _execute_task(self, context, task_orig)
           ^^^^^^^^^^^^^^^^^^^^^^^^^^^^^^^^^^^^^^^
  File "/home/airflow/.local/lib/python3.12/site-packages/airflow/models/taskinstance.py", line 768, in _execute_task
    result = _execute_callable(context=context, **execute_callable_kwargs)
             ^^^^^^^^^^^^^^^^^^^^^^^^^^^^^^^^^^^^^^^^^^^^^^^^^^^^^^^^^^^^^
  File "/home/airflow/.local/lib/python3.12/site-packages/airflow/models/taskinstance.py", line 734, in _execute_callable
    return ExecutionCallableRunner(
           ^^^^^^^^^^^^^^^^^^^^^^^^
  File "/home/airflow/.local/lib/python3.12/site-packages/airflow/utils/operator_helpers.py", line 252, in run
    return self.func(*args, **kwargs)
           ^^^^^^^^^^^^^^^^^^^^^^^^^^
  File "/home/airflow/.local/lib/python3.12/site-packages/airflow/models/baseoperator.py", line 424, in wrapper
    return func(self, *args, **kwargs)
           ^^^^^^^^^^^^^^^^^^^^^^^^^^^
  File "/home/airflow/.local/lib/python3.12/site-packages/airflow/operators/python.py", line 238, in execute
    return_value = self.execute_callable()
                   ^^^^^^^^^^^^^^^^^^^^^^^
  File "/home/airflow/.local/lib/python3.12/site-packages/airflow/operators/python.py", line 256, in execute_callable
    return runner.run(*self.op_args, **self.op_kwargs)
           ^^^^^^^^^^^^^^^^^^^^^^^^^^^^^^^^^^^^^^^^^^^
  File "/home/airflow/.local/lib/python3.12/site-packages/airflow/utils/operator_helpers.py", line 252, in run
    return self.func(*args, **kwargs)
           ^^^^^^^^^^^^^^^^^^^^^^^^^^
  File "/opt/airflow/dags/storeData.py", line 217, in model_data
    raise e
  File "/opt/airflow/dags/storeData.py", line 212, in model_data
    cur.execute(populate_dim_sql)
psycopg2.errors.InvalidColumnReference: there is no unique or exclusion constraint matching the ON CONFLICT specification

[2025-05-07T00:08:30.475+0000] {local_task_job_runner.py:266} INFO - Task exited with return code 1
[2025-05-07T00:08:30.541+0000] {taskinstance.py:3901} INFO - 0 downstream tasks scheduled from follow-on schedule check
[2025-05-07T00:08:30.579+0000] {local_task_job_runner.py:245} INFO - ::endgroup::
