[2025-05-08T21:50:34.181+0000] {local_task_job_runner.py:123} INFO - ::group::Pre task execution logs
[2025-05-08T21:50:34.226+0000] {taskinstance.py:2614} INFO - Dependencies all met for dep_context=non-requeueable deps ti=<TaskInstance: google_maps_reviews.model_data manual__2025-05-08T21:43:14.329156+00:00 [queued]>
[2025-05-08T21:50:34.245+0000] {taskinstance.py:2614} INFO - Dependencies all met for dep_context=requeueable deps ti=<TaskInstance: google_maps_reviews.model_data manual__2025-05-08T21:43:14.329156+00:00 [queued]>
[2025-05-08T21:50:34.247+0000] {taskinstance.py:2867} INFO - Starting attempt 2 of 3
[2025-05-08T21:50:34.273+0000] {taskinstance.py:2890} INFO - Executing <Task(PythonOperator): model_data> on 2025-05-08 21:43:14.329156+00:00
[2025-05-08T21:50:34.288+0000] {warnings.py:112} WARNING - /home/***/.local/lib/python3.12/site-packages/***/task/task_runner/standard_task_runner.py:70: DeprecationWarning: This process (pid=335) is multi-threaded, use of fork() may lead to deadlocks in the child.
  pid = os.fork()

[2025-05-08T21:50:34.292+0000] {standard_task_runner.py:72} INFO - Started process 357 to run task
[2025-05-08T21:50:34.292+0000] {standard_task_runner.py:104} INFO - Running: ['***', 'tasks', 'run', 'google_maps_reviews', 'model_data', 'manual__2025-05-08T21:43:14.329156+00:00', '--job-id', '895', '--raw', '--subdir', 'DAGS_FOLDER/***dag.py', '--cfg-path', '/tmp/tmpett1epgp']
[2025-05-08T21:50:34.295+0000] {standard_task_runner.py:105} INFO - Job 895: Subtask model_data
[2025-05-08T21:50:34.381+0000] {task_command.py:467} INFO - Running <TaskInstance: google_maps_reviews.model_data manual__2025-05-08T21:43:14.329156+00:00 [running]> on host f90cb465d7e0
[2025-05-08T21:50:34.552+0000] {taskinstance.py:3134} INFO - Exporting env vars: AIRFLOW_CTX_DAG_EMAIL='elkhalfimaryame@gmail.com' AIRFLOW_CTX_DAG_OWNER='***' AIRFLOW_CTX_DAG_ID='google_maps_reviews' AIRFLOW_CTX_TASK_ID='model_data' AIRFLOW_CTX_EXECUTION_DATE='2025-05-08T21:43:14.329156+00:00' AIRFLOW_CTX_TRY_NUMBER='2' AIRFLOW_CTX_DAG_RUN_ID='manual__2025-05-08T21:43:14.329156+00:00'
[2025-05-08T21:50:34.555+0000] {logging_mixin.py:190} INFO - Task instance is in running state
[2025-05-08T21:50:34.556+0000] {logging_mixin.py:190} INFO -  Previous state of the Task instance: queued
[2025-05-08T21:50:34.558+0000] {logging_mixin.py:190} INFO - Current task name:model_data state:running start_date:2025-05-08 21:50:34.227474+00:00
[2025-05-08T21:50:34.559+0000] {logging_mixin.py:190} INFO - Dag name:google_maps_reviews and current dag run status:running
[2025-05-08T21:50:34.561+0000] {taskinstance.py:732} INFO - ::endgroup::
[2025-05-08T21:50:34.580+0000] {base.py:84} INFO - Retrieving connection 'postgres_defaut'
[2025-05-08T21:50:34.594+0000] {taskinstance.py:3313} ERROR - Task failed with exception
Traceback (most recent call last):
  File "/home/airflow/.local/lib/python3.12/site-packages/airflow/models/taskinstance.py", line 768, in _execute_task
    result = _execute_callable(context=context, **execute_callable_kwargs)
             ^^^^^^^^^^^^^^^^^^^^^^^^^^^^^^^^^^^^^^^^^^^^^^^^^^^^^^^^^^^^^
  File "/home/airflow/.local/lib/python3.12/site-packages/airflow/models/taskinstance.py", line 734, in _execute_callable
    return ExecutionCallableRunner(
           ^^^^^^^^^^^^^^^^^^^^^^^^
  File "/home/airflow/.local/lib/python3.12/site-packages/airflow/utils/operator_helpers.py", line 252, in run
    return self.func(*args, **kwargs)
           ^^^^^^^^^^^^^^^^^^^^^^^^^^
  File "/home/airflow/.local/lib/python3.12/site-packages/airflow/models/baseoperator.py", line 424, in wrapper
    return func(self, *args, **kwargs)
           ^^^^^^^^^^^^^^^^^^^^^^^^^^^
  File "/home/airflow/.local/lib/python3.12/site-packages/airflow/operators/python.py", line 238, in execute
    return_value = self.execute_callable()
                   ^^^^^^^^^^^^^^^^^^^^^^^
  File "/home/airflow/.local/lib/python3.12/site-packages/airflow/operators/python.py", line 256, in execute_callable
    return runner.run(*self.op_args, **self.op_kwargs)
           ^^^^^^^^^^^^^^^^^^^^^^^^^^^^^^^^^^^^^^^^^^^
  File "/home/airflow/.local/lib/python3.12/site-packages/airflow/utils/operator_helpers.py", line 252, in run
    return self.func(*args, **kwargs)
           ^^^^^^^^^^^^^^^^^^^^^^^^^^
  File "/opt/airflow/dags/storeData.py", line 233, in model_data
    raise e
  File "/opt/airflow/dags/storeData.py", line 213, in model_data
    cur.execute(populate_dim_sql)
psycopg2.errors.InvalidColumnReference: there is no unique or exclusion constraint matching the ON CONFLICT specification

[2025-05-08T21:50:34.631+0000] {logging_mixin.py:190} INFO - Task instance in failure state
[2025-05-08T21:50:34.634+0000] {logging_mixin.py:190} INFO - Task start:2025-05-08 21:50:34.227474+00:00 end:2025-05-08 21:50:34.629570+00:00 duration:0.402096
[2025-05-08T21:50:34.635+0000] {logging_mixin.py:190} INFO - Task:<Task(PythonOperator): model_data> dag:<DAG: google_maps_reviews> dagrun:<DagRun google_maps_reviews @ 2025-05-08 21:43:14.329156+00:00: manual__2025-05-08T21:43:14.329156+00:00, state:running, queued_at: 2025-05-08 21:43:14.370818+00:00. externally triggered: True>
[2025-05-08T21:50:34.636+0000] {logging_mixin.py:190} INFO - Failure caused by there is no unique or exclusion constraint matching the ON CONFLICT specification
[2025-05-08T21:50:34.637+0000] {taskinstance.py:1226} INFO - Marking task as UP_FOR_RETRY. dag_id=google_maps_reviews, task_id=model_data, run_id=manual__2025-05-08T21:43:14.329156+00:00, execution_date=20250508T214314, start_date=20250508T215034, end_date=20250508T215034
[2025-05-08T21:50:34.672+0000] {warnings.py:112} WARNING - /home/***/.local/lib/python3.12/site-packages/***/utils/email.py:155: RemovedInAirflow3Warning: Fetching SMTP credentials from configuration variables will be deprecated in a future release. Please set credentials using a connection instead.
  send_mime_email(e_from=mail_from, e_to=recipients, mime_msg=msg, conn_id=conn_id, dryrun=dryrun)

[2025-05-08T21:50:34.674+0000] {email.py:272} INFO - Email alerting: attempt 1
[2025-05-08T21:50:35.615+0000] {email.py:283} INFO - Sent an alert email to ['elkhalfimaryame@gmail.com']
[2025-05-08T21:50:36.856+0000] {taskinstance.py:341} INFO - ::group::Post task execution logs
[2025-05-08T21:50:36.858+0000] {standard_task_runner.py:124} ERROR - Failed to execute job 895 for task model_data (there is no unique or exclusion constraint matching the ON CONFLICT specification
; 357)
Traceback (most recent call last):
  File "/home/airflow/.local/lib/python3.12/site-packages/airflow/task/task_runner/standard_task_runner.py", line 117, in _start_by_fork
    ret = args.func(args, dag=self.dag)
          ^^^^^^^^^^^^^^^^^^^^^^^^^^^^^
  File "/home/airflow/.local/lib/python3.12/site-packages/airflow/cli/cli_config.py", line 49, in command
    return func(*args, **kwargs)
           ^^^^^^^^^^^^^^^^^^^^^
  File "/home/airflow/.local/lib/python3.12/site-packages/airflow/utils/cli.py", line 116, in wrapper
    return f(*args, **kwargs)
           ^^^^^^^^^^^^^^^^^^
  File "/home/airflow/.local/lib/python3.12/site-packages/airflow/cli/commands/task_command.py", line 483, in task_run
    task_return_code = _run_task_by_selected_method(args, _dag, ti)
                       ^^^^^^^^^^^^^^^^^^^^^^^^^^^^^^^^^^^^^^^^^^^^
  File "/home/airflow/.local/lib/python3.12/site-packages/airflow/cli/commands/task_command.py", line 256, in _run_task_by_selected_method
    return _run_raw_task(args, ti)
           ^^^^^^^^^^^^^^^^^^^^^^^
  File "/home/airflow/.local/lib/python3.12/site-packages/airflow/cli/commands/task_command.py", line 341, in _run_raw_task
    return ti._run_raw_task(
           ^^^^^^^^^^^^^^^^^
  File "/home/airflow/.local/lib/python3.12/site-packages/airflow/utils/session.py", line 97, in wrapper
    return func(*args, session=session, **kwargs)
           ^^^^^^^^^^^^^^^^^^^^^^^^^^^^^^^^^^^^^^
  File "/home/airflow/.local/lib/python3.12/site-packages/airflow/models/taskinstance.py", line 3006, in _run_raw_task
    return _run_raw_task(
           ^^^^^^^^^^^^^^
  File "/home/airflow/.local/lib/python3.12/site-packages/airflow/models/taskinstance.py", line 274, in _run_raw_task
    TaskInstance._execute_task_with_callbacks(
  File "/home/airflow/.local/lib/python3.12/site-packages/airflow/models/taskinstance.py", line 3161, in _execute_task_with_callbacks
    result = self._execute_task(context, task_orig)
             ^^^^^^^^^^^^^^^^^^^^^^^^^^^^^^^^^^^^^^
  File "/home/airflow/.local/lib/python3.12/site-packages/airflow/models/taskinstance.py", line 3185, in _execute_task
    return _execute_task(self, context, task_orig)
           ^^^^^^^^^^^^^^^^^^^^^^^^^^^^^^^^^^^^^^^
  File "/home/airflow/.local/lib/python3.12/site-packages/airflow/models/taskinstance.py", line 768, in _execute_task
    result = _execute_callable(context=context, **execute_callable_kwargs)
             ^^^^^^^^^^^^^^^^^^^^^^^^^^^^^^^^^^^^^^^^^^^^^^^^^^^^^^^^^^^^^
  File "/home/airflow/.local/lib/python3.12/site-packages/airflow/models/taskinstance.py", line 734, in _execute_callable
    return ExecutionCallableRunner(
           ^^^^^^^^^^^^^^^^^^^^^^^^
  File "/home/airflow/.local/lib/python3.12/site-packages/airflow/utils/operator_helpers.py", line 252, in run
    return self.func(*args, **kwargs)
           ^^^^^^^^^^^^^^^^^^^^^^^^^^
  File "/home/airflow/.local/lib/python3.12/site-packages/airflow/models/baseoperator.py", line 424, in wrapper
    return func(self, *args, **kwargs)
           ^^^^^^^^^^^^^^^^^^^^^^^^^^^
  File "/home/airflow/.local/lib/python3.12/site-packages/airflow/operators/python.py", line 238, in execute
    return_value = self.execute_callable()
                   ^^^^^^^^^^^^^^^^^^^^^^^
  File "/home/airflow/.local/lib/python3.12/site-packages/airflow/operators/python.py", line 256, in execute_callable
    return runner.run(*self.op_args, **self.op_kwargs)
           ^^^^^^^^^^^^^^^^^^^^^^^^^^^^^^^^^^^^^^^^^^^
  File "/home/airflow/.local/lib/python3.12/site-packages/airflow/utils/operator_helpers.py", line 252, in run
    return self.func(*args, **kwargs)
           ^^^^^^^^^^^^^^^^^^^^^^^^^^
  File "/opt/airflow/dags/storeData.py", line 233, in model_data
    raise e
  File "/opt/airflow/dags/storeData.py", line 213, in model_data
    cur.execute(populate_dim_sql)
psycopg2.errors.InvalidColumnReference: there is no unique or exclusion constraint matching the ON CONFLICT specification

[2025-05-08T21:50:36.884+0000] {local_task_job_runner.py:266} INFO - Task exited with return code 1
[2025-05-08T21:50:36.933+0000] {taskinstance.py:3901} INFO - 0 downstream tasks scheduled from follow-on schedule check
[2025-05-08T21:50:36.937+0000] {local_task_job_runner.py:245} INFO - ::endgroup::
